<?xml version="1.0" ?>
<sdf version="1.5">
  <model name="amr_car">
    <static>false</static>
    <link name="chassis">
      <collision name="collision">
        <geometry>
          <mesh>
            <uri>model://amr_car/meshes/chassis.stl</uri>
            <scale>0.01 0.01 0.01</scale>
          </mesh>
        </geometry>
        <surface>
          <friction>
            <ode>
              <mu>100</mu>
              <mu2>50</mu2>
            </ode>
          </friction>
        </surface>
      </collision>
      <visual name="visual">
        <geometry>
          <mesh>
            <uri>model://amr_car/meshes/chassis.stl</uri>
            <scale>0.01 0.01 0.01</scale>
          </mesh>
        </geometry>
        <material>
          <script>
            <uri>file://media/materials/scripts/gazebo.material</uri>
            <name>Gazebo/Blue</name>
          </script>
        </material>
      </visual>
    </link>
    
    <!-- whell -->
    <link name="left_wheel">
      <collision name="collision">
        <geometry>
          <mesh>
            <uri>model://amr_car/meshes/left_wheel.stl</uri>
            <scale>0.01 0.01 0.01</scale>
          </mesh>
        </geometry>
        <surface>
          <friction>
            <ode>
              <mu>100</mu>
              <mu2>50</mu2>
            </ode>
          </friction>
        </surface>
      </collision>
      <visual name="visual">
        <geometry>
          <mesh>
            <uri>model://amr_car/meshes/left_wheel.stl</uri>
            <scale>0.01 0.01 0.01</scale>
          </mesh>
        </geometry>
        <material>
          <script>
            <uri>file://media/materials/scripts/gazebo.material</uri>
            <name>Gazebo/Black</name>
          </script>
        </material>
      </visual>
    </link>
    <link name="right_wheel">
      <collision name="collision">
        <geometry>
          <mesh>
            <uri>model://amr_car/meshes/right_wheel.stl</uri>
            <scale>0.01 0.01 0.01</scale>
          </mesh>
        </geometry>
        <surface>
          <friction>
            <ode>
              <mu>100</mu>
              <mu2>50</mu2>
            </ode>
          </friction>
        </surface>
      </collision>
      <visual name="visual">
        <geometry>
          <mesh>
            <uri>model://amr_car/meshes/right_wheel.stl</uri>
            <scale>0.01 0.01 0.01</scale>
          </mesh>
        </geometry>
        <material>
          <script>
            <uri>file://media/materials/scripts/gazebo.material</uri>
            <name>Gazebo/Black</name>
          </script>
        </material>
      </visual>
    </link>
    <joint type="revolute" name="left_wheel_hinge">
      <pose>0.3 0 0.08 0 0 0</pose>
      <child>left_wheel</child>
      <parent>chassis</parent>
      <axis>
        <xyz>1 0 0</xyz>
      </axis>
    </joint>
    <joint type="revolute" name="right_wheel_hinge">
      <pose>-0.3 0 0.08 0 0 0</pose>
      <child>right_wheel</child>
      <parent>chassis</parent>
      <axis>
        <xyz>1 0 0</xyz>
      </axis>
    </joint>
    <plugin name="left_wheel_drive_controller" filename="libgazebo_ros_diff_drive.so">
      <odometrySource>world</odometrySource>
      <publishOdomTF>true</publishOdomTF>
      <publishWheelTF>false</publishWheelTF>
      <publishTf>true</publishTf>
      <publishWheelJointState>true</publishWheelJointState>
      <legacyMode>false</legacyMode>
      
      <wheelAcceleration>1</wheelAcceleration>
      <wheelTorque>10</wheelTorque>
      <rosDebugLevel>na</rosDebugLevel>


      <alwaysOn>true</alwaysOn>
      <updateRate>30</updateRate>
      <leftJoint>left_wheel_hinge</leftJoint>
      <rightJoint>right_wheel_hinge</rightJoint>
      <wheelSeparation>0.5380</wheelSeparation>
      <wheelDiameter>0.2410</wheelDiameter>
      <torque>20</torque>
      <commandTopic>cmd_vel</commandTopic>
      <odometryTopic>odom</odometryTopic>
      <odometryFrame>odom</odometryFrame>
      <robotBaseFrame>base_footprint</robotBaseFrame>
    </plugin>

    <!-- caster -->
    <link name="front_caster">
      <collision name="collision">
        <geometry>
          <mesh>
            <uri>model://amr_car/meshes/front_caster.stl</uri>
            <scale>0.01 0.01 0.01</scale>
          </mesh>
        </geometry>
        <surface>
          <friction>
            <ode>
              <mu>0</mu>
              <mu2>0</mu2>
            </ode>
          </friction>
        </surface>
      </collision>
      <visual name="visual">
        <geometry>
          <mesh>
            <uri>model://amr_car/meshes/front_caster.stl</uri>
            <scale>0.01 0.01 0.01</scale>
          </mesh>
        </geometry>
        <material>
          <script>
            <uri>file://media/materials/scripts/gazebo.material</uri>
            <name>Gazebo/Gray</name>
          </script>
        </material>
      </visual>
    </link>
    <link name="back_caster">
      <collision name="collision">
        <geometry>
          <mesh>
            <uri>model://amr_car/meshes/back_caster.stl</uri>
            <scale>0.01 0.01 0.01</scale>
          </mesh>
        </geometry>
        <surface>
          <friction>
            <ode>
              <mu>0</mu>
              <mu2>0</mu2>
            </ode>
          </friction>
        </surface>
      </collision>
      <visual name="visual">
        <geometry>
          <mesh>
            <uri>model://amr_car/meshes/back_caster.stl</uri>
            <scale>0.01 0.01 0.01</scale>
          </mesh>
        </geometry>
        <material>
          <script>
            <uri>file://media/materials/scripts/gazebo.material</uri>
            <name>Gazebo/Gray</name>
          </script>
        </material>
      </visual>
    </link>
    <joint type="fixed" name="front_caster_joint">
      <child>front_caster</child>
      <parent>chassis</parent>
    </joint>
    <joint type="fixed" name="back_caster_joint">
      <child>back_caster</child>
      <parent>chassis</parent>
    </joint>


    <!-- Lidar sick_tim551.stl-->
    <link name="sick_tim551">
      <collision name="collision">
        <geometry>
          <mesh>
            <uri>model://amr_car/meshes/sick_tim551.stl</uri>
            <scale>0.01 0.01 0.01</scale>
          </mesh>
        </geometry>
      </collision>
      <visual name="visual">
        <geometry>
          <mesh>
            <uri>model://amr_car/meshes/sick_tim551.stl</uri>
            <scale>0.01 0.01 0.01</scale>
          </mesh>
        </geometry>
        <material>
          <script>
            <uri>file://media/materials/scripts/gazebo.material</uri>
            <name>Gazebo/Gray</name>
          </script>
        </material>
      </visual>
      <sensor type="ray" name="LiDAR">
        <pose>0 -0.287 0.267341 0 0 0</pose>
        <ray>
          <scan>
            <horizontal>
              <samples>640</samples>
              <resolution>1</resolution>
              <min_angle>3.14159</min_angle>
              <max_angle>6.283185</max_angle>
            </horizontal>
          </scan>
          <range>
            <min>0.1</min>
            <max>10</max>
            <resolution>0.01</resolution>
          </range>
        </ray>
        <plugin name="laser" filename="libgazebo_ros_laser.so" />
        <always_on>1</always_on>
        <update_rate>30</update_rate>
        <visualize>true</visualize>
      </sensor>
    </link>
    <joint type="fixed" name="laser_joint">
      <child>sick_tim551</child>
      <parent>chassis</parent>
    </joint>
  </model>
</sdf>
